Workbook
Name Abrechnung: db_Abrechnung!$A$1:$K$183
Name Druckbereich_keller: Keller!$A$1:$L$22
Name Druckbereich_pergola: Garten!$A$1:$R$20
Name Druckbereich_pergola: Pergola!$A$1:$R$20
Name Druckbereich_terrasse: Terrasse!$A$1:$R$21
Name Druckbereich_ubersicht: Übersicht!$A$1:$L$14
Name Druckbereich_WNF: Wohnfläche!$A$1:$G$195
Name tbl_keller: Tabelle15[]
Name tbl_keller: Tabelle15[]
Name tbl_keller: Tabelle15[]
Name tbl_terrasse: Tabelle15768[]
Name tbl_terrasse: Tabelle1576[]
Name tbl_terrasse: Tabelle157[]

Sheet Stammdaten
A1: Projekt | D1: Krusdorf
A3: Strasse, Hr. | B3: Krusdorf 72
A4: PLZ - Ort | B4: 8345 - Krusdorf
A5: Gemeinde | B5: Straden
A7: Stockwerk | B7: 2
A8: Objektart | B8: Einfamilienhaus
A10: Start | B10: 42663
A11: kalk. Ende | B11: 42826

Sheet Flächen
B2: Flächenaufstellung
B3: Bezeichnung | C3: Geschoss | D3: Flächenart | E3: Bau | F3: Fläche | G3: Summe
B4: ERDGESCHOSS
B5: Vorzimmer | C5: EG | D5: WNF | E5: x | F5: 12.11 | G5: =SUM(F5:F13) -> 107.9
B6: WC | C6: EG | D6: WNF | E6: x | F6: 2.14
B7: Küche | C7: EG | D7: WNF | E7: x | F7: 12.23
B8: Essen / Wohnen | C8: EG | D8: WNF | E8: x | F8: 39.65
B9: Gang | C9: EG | D9: WNF | E9: x | F9: 2.7
B10: Stiegenhaus EG-OG | C10: OG | D10: WNF | E10: x | F10: 3
B11: Teichzimmer | C11: EG | D11: WNF | E11: x | F11: 12.21
B12: Bad | C12: EG | D12: WNF | E12: x | F12: 9.86
B13: Garagenzimmer | C13: EG | D13: WNF | E13: x | F13: 14
B14: OBERGESCHOSS
B15: Diele | C15: OG | D15: WNF | E15: x | F15: 18.4 | G15: =SUM(F15:F21) -> 104.03
B16: Bad | C16: OG | D16: WNF | E16: x | F16: 6.8
B17: Appartment | C17: OG | D17: WNF | E17: x | F17: 18.76
B18: Schlafzimmer | C18: OG | D18: WNF | E18: x | F18: 19.09
B19: Balkonzimmer | C19: OG | D19: WNF | E19: x | F19: 15.7
B20: Büro | C20: OG | D20: WNF | E20: x | F20: 17.58
B21: Stauraum | C21: OG | D21: WNF | E21: x | F21: 7.7
B22: KELLERGESCHOSS
B23: Stiegenhaus EG-KG | C23: KG | D23: FF | F23: 3 | G23: =SUM(F23:F29) -> 73.36
B24: Vorraum | C24: KG | D24: FF | F24: 9
B25: Sauna | C25: KG | D25: FF | F25: 16.36
B26: Heizraum | C26: KG | D26: FF | F26: 13.37
B27: Keller 1 | C27: KG | D27: FF | F27: 12.03
B28: Keller 2 | C28: KG | D28: FF | F28: 11
B29: Lager | C29: KG | D29: FF | F29: 8.6
B30: SONSTIGE FLÄCHEN
B31: Garage | C31: EG | D31: FF | F31: 15.76 | G31: =SUM(F31:F33) -> 37.06
B32: Balkon | C32: OG | D32: Frei | F32: 11.3
B33: Terrasse | C33: EG | D33: Frei | F33: 10
B34: Nutzfläche gesamt in m² | G34: =SUM(G5:G33) -> 322.35
B37: =$B$4 -> ERDGESCHOSS | F37: =$G$5 -> 107.9 | G37: =SUM(F37:F38) -> 211.93
B38: =$B$14 -> OBERGESCHOSS | F38: =$G$15 -> 104.03
B39: =$B$22 -> KELLERGESCHOSS | F39: =$G$23 -> 73.36
B40: =$B$30 -> SONSTIGE FLÄCHEN | F40: =$G$31 -> 37.06
B42: BAUPHASE 1 | C42: x | G42: =SUMIF(E5:E33,C42,F5:F33) -> 211.93

Sheet Anschaffung
A1: Anschaffungskosten | F1: =G1/Flächen!$G$37 -> 1184.5421 | G1: =SUM(G2:G15) -> 251040
B2: Kaufpreis | G2: =SUM(F4:F4) -> 240000
B3: Rech-Datum | C3: Beschreibung | D3: netto | E3: Ust | F3: brutto
D4: =F4/(1+E4) -> 240000 | E4: 0 | F4: 240000
B6: Kaufvertragserrichtung | G6: =SUM(F8:F8) -> 0
B7: Rech-Datum | C7: Beschreibung | D7: netto | E7: Ust | F7: brutto
D8: =F8/(1+E8) -> 0 | E8: 0.2 | F8: 0
B9: Grunderwerbsteuer | G9: =SUM(F11:F11) -> 8400
B10: Rech-Datum | C10: Beschreibung | E10: Ust | F10: brutto
E11: 0.035 | F11: =G2*E11 -> 8400
B12: Eintragungsgebühr | G12: =SUM(F14:F14) -> 2640
B13: Rech-Datum | C13: Beschreibung | E13: Ust | F13: brutto
E14: 0.011 | F14: =G2*E14 -> 2640
B15: Sonstiges | G15: =SUM(F17:F20) -> 0
B16: Rech-Datum | C16: Beschreibung | D16: netto | E16: Ust | F16: brutto
D17: =F17/(1+E17) -> 0 | E17: 0.2 | F17: 0
D18: =F18/(1+E18) -> 0 | E18: 0.2 | F18: 0
D19: =F19/(1+E19) -> 0 | E19: 0.2 | F19: 0
D20: =F20/(1+E20) -> 0 | E20: 0.2 | F20: 0

Sheet Betriebskosten
A1: Betriebskosten | F1: =G1/Flächen!$G$37 -> 2.9962724 | G1: =SUM(G2:G31) -> 635
A2: Heizung | B2: Heizöl Roth | G2: =SUM(F4:F7) -> 437
B3: Rech-Datum | C3: Beschreibung | D3: netto | E3: Ust | F3: brutto
B4: 42738 | C4: Baustelle | D4: =F4/(1+E4) -> 364.16667 | E4: 0.2 | F4: 437
D5: =F5/(1+E5) -> 0 | E5: 0.2 | F5: 0
D6: =F6/(1+E6) -> 0 | E6: 0.2 | F6: 0
D7: =F7/(1+E7) -> 0 | E7: 0.2 | F7: 0
A9: Heizung | B9: STRANZL | G9: =SUM(F11:F14) -> 198
B10: Rech-Datum | C10: Beschreibung | D10: netto | E10: Ust | F10: brutto
B11: 43203 | C11: Servicevertrag | D11: =F11/(1+E11) -> 165 | E11: 0.2 | F11: 198
D12: =F12/(1+E12) -> 0 | E12: 0.2 | F12: 0
D13: =F13/(1+E13) -> 0 | E13: 0.2 | F13: 0
D14: =F14/(1+E14) -> 0 | E14: 0.2 | F14: 0
A16: Strom | B16: Energie Steiermark | G16: =SUM(F18:F21) -> 0
B17: Rech-Datum | C17: Beschreibung | D17: netto | E17: Ust | F17: brutto
B18: 42736 | C18: Vorschreibung pro Monat | D18: =F18/(1+E18) -> 0 | E18: 0.2 | F18: 0
D19: =F19/(1+E19) -> 0 | E19: 0.2 | F19: 0
D20: =F20/(1+E20) -> 0 | E20: 0.2 | F20: 0
D21: =F21/(1+E21) -> 0 | E21: 0.2 | F21: 0
A22: Versicherung | B22: Hausversicherung | G22: =SUM(F24:F24) -> 0
B23: Rech-Datum | C23: Beschreibung | D23: netto | E23: Ust | F23: brutto
B24: 42736 | D24: 0 | E24: 0.2 | F24: 0
A25: Gemeindeabgaben | B25: Straden | G25: =SUM(F27:F30) -> 0
B26: Rech-Datum | C26: Beschreibung | D26: netto | E26: Ust | F26: brutto
B27: 42736 | C27: Wasser | D27: =F27/(1+E27) -> 0 | E27: 0.1 | F27: 0
C28: Kanal | D28: =F28/(1+E28) -> 0 | E28: 0.1 | F28: 0
C29: Grundsteuer | D29: =F29/(1+E29) -> 0 | E29: 0.1 | F29: 0
D30: =F30/(1+E30) -> 0 | E30: 0.1 | F30: 0
A31: sonstiges | B31: Sonstiges | G31: =SUM(F33:F36) -> 0
B32: Rech-Datum | C32: Beschreibung | D32: netto | E32: Ust | F32: brutto
C33: Orf Gebühren | D33: =F33/(1+E33) -> 0 | E33: 0.2 | F33: 0
D34: =F34/(1+E34) -> 0 | E34: 0.2 | F34: 0
D35: =F35/(1+E35) -> 0 | E35: 0.2 | F35: 0
D36: =F36/(1+E36) -> 0 | E36: 0.2 | F36: 0

Sheet Baukosten 1.0
A3: EG | B3: =Flächen!B37 -> ERDGESCHOSS | D3: =Flächen!$G$5 -> 107.9 | E3: =SUM(D3:D6) -> 322.35 | F3: MALER | G3: =I3/D3 -> 48.729101 | H3: =SUM(H11:H36)/E3 -> 101.75527 | I3: {=SUM(IF(Tabelle1[Ebene]=A3,IF(Tabelle1[Gewerk]=F3,Tabelle1[Pos.Preis])))} -> 5257.87 | K3: =L3/D3 -> 206.77924 | L3: {=SUM(IF(Tabelle1[Ebene]=A3,Tabelle1[Pos.Preis]))} -> 22311.48 | M3: =SUM(L3:L6) -> 34337.19
A4: 1. OG | B4: =Flächen!B38 -> OBERGESCHOSS | D4: =Flächen!F38 -> 104.03 | G4: =I4/D4 -> 25.303182 | I4: {=SUM(IF(Tabelle1[Ebene]=A4,IF(Tabelle1[Gewerk]=F3,Tabelle1[Pos.Preis])))} -> 2632.29 | K4: =L4/D4 -> 84.434394 | L4: {=SUM(IF(Tabelle1[Ebene]=A4,Tabelle1[Pos.Preis]))} -> 8783.71
A5: KG | B5: =Flächen!B39 -> KELLERGESCHOSS | D5: =Flächen!F39 -> 73.36 | G5: =I5/D5 -> 0 | I5: {=SUM(IF(Tabelle1[Ebene]=A5,IF(Tabelle1[Gewerk]=F3,Tabelle1[Pos.Preis])))} -> 0 | K5: =L5/D5 -> 6.5430752 | L5: {=SUM(IF(Tabelle1[Ebene]=A5,Tabelle1[Pos.Preis]))} -> 480
A6: SF | B6: =Flächen!B40 -> SONSTIGE FLÄCHEN | D6: =Flächen!F40 -> 37.06 | G6: =I6/D6 -> 0 | I6: {=SUM(IF(Tabelle1[Ebene]=A6,IF(Tabelle1[Gewerk]=F3,Tabelle1[Pos.Preis])))} -> 0 | K6: =L6/D6 -> 74.527793 | L6: {=SUM(IF(Tabelle1[Ebene]=A6,Tabelle1[Pos.Preis]))} -> 2762
H10: Hoch | K10: Mittel | L10: Nieder | M10: GESAMT
B11: Nebenkosten | H11: {=SUM(IF(Tabelle1[Raum]=B11,IF(Tabelle1[Prio]=$H$10,Tabelle1[Pos.Preis])))} -> 0 | K11: {=SUM(IF(Tabelle1[Raum]=$B11,IF(Tabelle1[Prio]=$K$10,Tabelle1[Pos.Preis])))} -> 0 | L11: {=SUM(IF(Tabelle1[Raum]=$B11,IF(Tabelle1[Prio]=$L$10,Tabelle1[Pos.Preis])))} -> 0 | M11: {=SUM(IF(Tabelle1[Raum]=B11,Tabelle1[Pos.Preis]))} -> 0
A12: EG | B12: Vorzimmer | H12: {=SUM(IF(Tabelle1[Raum]=B12,IF(Tabelle1[Prio]=$H$10,Tabelle1[Pos.Preis])))} -> 889.63 | K12: {=SUM(IF(Tabelle1[Raum]=$B12,IF(Tabelle1[Prio]=$K$10,Tabelle1[Pos.Preis])))} -> 0 | L12: {=SUM(IF(Tabelle1[Raum]=$B12,IF(Tabelle1[Prio]=$L$10,Tabelle1[Pos.Preis])))} -> 363.3 | M12: {=SUM(IF(Tabelle1[Raum]=B12,Tabelle1[Pos.Preis]))} -> 1252.93 | N12: =SUM(M12:M19) -> 21635.4
A13: EG | B13: Küche | H13: {=SUM(IF(Tabelle1[Raum]=B13,IF(Tabelle1[Prio]=$H$10,Tabelle1[Pos.Preis])))} -> 2961.31 | K13: {=SUM(IF(Tabelle1[Raum]=$B13,IF(Tabelle1[Prio]=$K$10,Tabelle1[Pos.Preis])))} -> 0 | L13: {=SUM(IF(Tabelle1[Raum]=$B13,IF(Tabelle1[Prio]=$L$10,Tabelle1[Pos.Preis])))} -> 0 | M13: {=SUM(IF(Tabelle1[Raum]=B13,Tabelle1[Pos.Preis]))} -> 2961.31
A14: EG | B14: Essen / Wohnen | H14: {=SUM(IF(Tabelle1[Raum]=B14,IF(Tabelle1[Prio]=$H$10,Tabelle1[Pos.Preis])))} -> 6501.45 | K14: {=SUM(IF(Tabelle1[Raum]=$B14,IF(Tabelle1[Prio]=$K$10,Tabelle1[Pos.Preis])))} -> 0 | L14: {=SUM(IF(Tabelle1[Raum]=$B14,IF(Tabelle1[Prio]=$L$10,Tabelle1[Pos.Preis])))} -> 0 | M14: {=SUM(IF(Tabelle1[Raum]=B14,Tabelle1[Pos.Preis]))} -> 6501.45
A15: EG | B15: Gang | H15: {=SUM(IF(Tabelle1[Raum]=B15,IF(Tabelle1[Prio]=$H$10,Tabelle1[Pos.Preis])))} -> 296.4 | K15: {=SUM(IF(Tabelle1[Raum]=$B15,IF(Tabelle1[Prio]=$K$10,Tabelle1[Pos.Preis])))} -> 0 | L15: {=SUM(IF(Tabelle1[Raum]=$B15,IF(Tabelle1[Prio]=$L$10,Tabelle1[Pos.Preis])))} -> 0 | M15: {=SUM(IF(Tabelle1[Raum]=B15,Tabelle1[Pos.Preis]))} -> 296.4
A16: EG | B16: Stiegenhaus EG-OG | H16: {=SUM(IF(Tabelle1[Raum]=B16,IF(Tabelle1[Prio]=$H$10,Tabelle1[Pos.Preis])))} -> 91 | K16: {=SUM(IF(Tabelle1[Raum]=$B16,IF(Tabelle1[Prio]=$K$10,Tabelle1[Pos.Preis])))} -> 0 | L16: {=SUM(IF(Tabelle1[Raum]=$B16,IF(Tabelle1[Prio]=$L$10,Tabelle1[Pos.Preis])))} -> 0 | M16: {=SUM(IF(Tabelle1[Raum]=B16,Tabelle1[Pos.Preis]))} -> 91
A17: EG | B17: Teichzimmer | H17: {=SUM(IF(Tabelle1[Raum]=B17,IF(Tabelle1[Prio]=$H$10,Tabelle1[Pos.Preis])))} -> 2510.29 | K17: {=SUM(IF(Tabelle1[Raum]=$B17,IF(Tabelle1[Prio]=$K$10,Tabelle1[Pos.Preis])))} -> 0 | L17: {=SUM(IF(Tabelle1[Raum]=$B17,IF(Tabelle1[Prio]=$L$10,Tabelle1[Pos.Preis])))} -> 0 | M17: {=SUM(IF(Tabelle1[Raum]=B17,Tabelle1[Pos.Preis]))} -> 2510.29
A18: EG | B18: Bad | H18: {=SUM(IF(Tabelle1[Raum]=B18,IF(Tabelle1[Prio]=$H$10,Tabelle1[Pos.Preis])))} -> 5543.02 | K18: {=SUM(IF(Tabelle1[Raum]=$B18,IF(Tabelle1[Prio]=$K$10,Tabelle1[Pos.Preis])))} -> 0 | L18: {=SUM(IF(Tabelle1[Raum]=$B18,IF(Tabelle1[Prio]=$L$10,Tabelle1[Pos.Preis])))} -> 0 | M18: {=SUM(IF(Tabelle1[Raum]=B18,Tabelle1[Pos.Preis]))} -> 5543.02
A19: EG | B19: Garagenzimmer | H19: {=SUM(IF(Tabelle1[Raum]=B19,IF(Tabelle1[Prio]=$H$10,Tabelle1[Pos.Preis])))} -> 2479 | K19: {=SUM(IF(Tabelle1[Raum]=$B19,IF(Tabelle1[Prio]=$K$10,Tabelle1[Pos.Preis])))} -> 0 | L19: {=SUM(IF(Tabelle1[Raum]=$B19,IF(Tabelle1[Prio]=$L$10,Tabelle1[Pos.Preis])))} -> 0 | M19: {=SUM(IF(Tabelle1[Raum]=B19,Tabelle1[Pos.Preis]))} -> 2479
A20: 1. OG | B20: Diele | H20: {=SUM(IF(Tabelle1[Raum]=B20,IF(Tabelle1[Prio]=$H$10,Tabelle1[Pos.Preis])))} -> 1548.4 | K20: {=SUM(IF(Tabelle1[Raum]=$B20,IF(Tabelle1[Prio]=$K$10,Tabelle1[Pos.Preis])))} -> 0 | L20: {=SUM(IF(Tabelle1[Raum]=$B20,IF(Tabelle1[Prio]=$L$10,Tabelle1[Pos.Preis])))} -> 0 | M20: {=SUM(IF(Tabelle1[Raum]=B20,Tabelle1[Pos.Preis]))} -> 1548.4 | N20: =SUM(M20:M26) -> 8793.71
A21: 1. OG | B21: Bad - OG | H21: {=SUM(IF(Tabelle1[Raum]=B21,IF(Tabelle1[Prio]=$H$10,Tabelle1[Pos.Preis])))} -> 699.6 | K21: {=SUM(IF(Tabelle1[Raum]=$B21,IF(Tabelle1[Prio]=$K$10,Tabelle1[Pos.Preis])))} -> 0 | L21: {=SUM(IF(Tabelle1[Raum]=$B21,IF(Tabelle1[Prio]=$L$10,Tabelle1[Pos.Preis])))} -> 0 | M21: {=SUM(IF(Tabelle1[Raum]=B21,Tabelle1[Pos.Preis]))} -> 699.6
A22: 1. OG | B22: Apartment | H22: {=SUM(IF(Tabelle1[Raum]=B22,IF(Tabelle1[Prio]=$H$10,Tabelle1[Pos.Preis])))} -> 1505.76 | K22: {=SUM(IF(Tabelle1[Raum]=$B22,IF(Tabelle1[Prio]=$K$10,Tabelle1[Pos.Preis])))} -> 0 | L22: {=SUM(IF(Tabelle1[Raum]=$B22,IF(Tabelle1[Prio]=$L$10,Tabelle1[Pos.Preis])))} -> 0 | M22: {=SUM(IF(Tabelle1[Raum]=B22,Tabelle1[Pos.Preis]))} -> 1505.76
A23: 1. OG | B23: Schlafzimmer | H23: {=SUM(IF(Tabelle1[Raum]=B23,IF(Tabelle1[Prio]=$H$10,Tabelle1[Pos.Preis])))} -> 1700.47 | K23: {=SUM(IF(Tabelle1[Raum]=$B23,IF(Tabelle1[Prio]=$K$10,Tabelle1[Pos.Preis])))} -> 0 | L23: {=SUM(IF(Tabelle1[Raum]=$B23,IF(Tabelle1[Prio]=$L$10,Tabelle1[Pos.Preis])))} -> 0 | M23: {=SUM(IF(Tabelle1[Raum]=B23,Tabelle1[Pos.Preis]))} -> 1700.47
A24: 1. OG | B24: Balkonzimmer | H24: {=SUM(IF(Tabelle1[Raum]=B24,IF(Tabelle1[Prio]=$H$10,Tabelle1[Pos.Preis])))} -> 1283.2 | K24: {=SUM(IF(Tabelle1[Raum]=$B24,IF(Tabelle1[Prio]=$K$10,Tabelle1[Pos.Preis])))} -> 0 | L24: {=SUM(IF(Tabelle1[Raum]=$B24,IF(Tabelle1[Prio]=$L$10,Tabelle1[Pos.Preis])))} -> 0 | M24: {=SUM(IF(Tabelle1[Raum]=B24,Tabelle1[Pos.Preis]))} -> 1283.2
A25: 1. OG | B25: Büro | H25: {=SUM(IF(Tabelle1[Raum]=B25,IF(Tabelle1[Prio]=$H$10,Tabelle1[Pos.Preis])))} -> 1426.08 | K25: {=SUM(IF(Tabelle1[Raum]=$B25,IF(Tabelle1[Prio]=$K$10,Tabelle1[Pos.Preis])))} -> 0 | L25: {=SUM(IF(Tabelle1[Raum]=$B25,IF(Tabelle1[Prio]=$L$10,Tabelle1[Pos.Preis])))} -> 25 | M25: {=SUM(IF(Tabelle1[Raum]=B25,Tabelle1[Pos.Preis]))} -> 1451.08
A26: 1. OG | B26: Stauraum | H26: {=SUM(IF(Tabelle1[Raum]=B26,IF(Tabelle1[Prio]=$H$10,Tabelle1[Pos.Preis])))} -> 605.2 | K26: {=SUM(IF(Tabelle1[Raum]=$B26,IF(Tabelle1[Prio]=$K$10,Tabelle1[Pos.Preis])))} -> 0 | L26: {=SUM(IF(Tabelle1[Raum]=$B26,IF(Tabelle1[Prio]=$L$10,Tabelle1[Pos.Preis])))} -> 0 | M26: {=SUM(IF(Tabelle1[Raum]=B26,Tabelle1[Pos.Preis]))} -> 605.2
A27: KG | B27: Stiegenhaus EG-KG | H27: {=SUM(IF(Tabelle1[Raum]=B27,IF(Tabelle1[Prio]=$H$10,Tabelle1[Pos.Preis])))} -> 0 | K27: {=SUM(IF(Tabelle1[Raum]=$B27,IF(Tabelle1[Prio]=$K$10,Tabelle1[Pos.Preis])))} -> 380 | L27: {=SUM(IF(Tabelle1[Raum]=$B27,IF(Tabelle1[Prio]=$L$10,Tabelle1[Pos.Preis])))} -> 15 | M27: {=SUM(IF(Tabelle1[Raum]=B27,Tabelle1[Pos.Preis]))} -> 395 | N27: =SUM(M27:M36) -> 3242
A28: KG | B28: Vorraum | H28: {=SUM(IF(Tabelle1[Raum]=B28,IF(Tabelle1[Prio]=$H$10,Tabelle1[Pos.Preis])))} -> 0 | K28: {=SUM(IF(Tabelle1[Raum]=$B28,IF(Tabelle1[Prio]=$K$10,Tabelle1[Pos.Preis])))} -> 0 | L28: {=SUM(IF(Tabelle1[Raum]=$B28,IF(Tabelle1[Prio]=$L$10,Tabelle1[Pos.Preis])))} -> 0 | M28: {=SUM(IF(Tabelle1[Raum]=B28,Tabelle1[Pos.Preis]))} -> 0
A29: KG | B29: Sauna | H29: {=SUM(IF(Tabelle1[Raum]=B29,IF(Tabelle1[Prio]=$H$10,Tabelle1[Pos.Preis])))} -> 0 | K29: {=SUM(IF(Tabelle1[Raum]=$B29,IF(Tabelle1[Prio]=$K$10,Tabelle1[Pos.Preis])))} -> 0 | L29: {=SUM(IF(Tabelle1[Raum]=$B29,IF(Tabelle1[Prio]=$L$10,Tabelle1[Pos.Preis])))} -> 0 | M29: {=SUM(IF(Tabelle1[Raum]=B29,Tabelle1[Pos.Preis]))} -> 0
A30: KG | B30: Heizraum | H30: {=SUM(IF(Tabelle1[Raum]=B30,IF(Tabelle1[Prio]=$H$10,Tabelle1[Pos.Preis])))} -> 0 | K30: {=SUM(IF(Tabelle1[Raum]=$B30,IF(Tabelle1[Prio]=$K$10,Tabelle1[Pos.Preis])))} -> 0 | L30: {=SUM(IF(Tabelle1[Raum]=$B30,IF(Tabelle1[Prio]=$L$10,Tabelle1[Pos.Preis])))} -> 35 | M30: {=SUM(IF(Tabelle1[Raum]=B30,Tabelle1[Pos.Preis]))} -> 35
A31: KG | B31: Keller 1 | H31: {=SUM(IF(Tabelle1[Raum]=B31,IF(Tabelle1[Prio]=$H$10,Tabelle1[Pos.Preis])))} -> 0 | K31: {=SUM(IF(Tabelle1[Raum]=$B31,IF(Tabelle1[Prio]=$K$10,Tabelle1[Pos.Preis])))} -> 0 | L31: {=SUM(IF(Tabelle1[Raum]=$B31,IF(Tabelle1[Prio]=$L$10,Tabelle1[Pos.Preis])))} -> 30 | M31: {=SUM(IF(Tabelle1[Raum]=B31,Tabelle1[Pos.Preis]))} -> 30
A32: KG | B32: Keller 2 | H32: {=SUM(IF(Tabelle1[Raum]=B32,IF(Tabelle1[Prio]=$H$10,Tabelle1[Pos.Preis])))} -> 0 | K32: {=SUM(IF(Tabelle1[Raum]=$B32,IF(Tabelle1[Prio]=$K$10,Tabelle1[Pos.Preis])))} -> 0 | L32: {=SUM(IF(Tabelle1[Raum]=$B32,IF(Tabelle1[Prio]=$L$10,Tabelle1[Pos.Preis])))} -> 10 | M32: {=SUM(IF(Tabelle1[Raum]=B32,Tabelle1[Pos.Preis]))} -> 10
A33: KG | B33: Lager | H33: {=SUM(IF(Tabelle1[Raum]=B33,IF(Tabelle1[Prio]=$H$10,Tabelle1[Pos.Preis])))} -> 0 | K33: {=SUM(IF(Tabelle1[Raum]=$B33,IF(Tabelle1[Prio]=$K$10,Tabelle1[Pos.Preis])))} -> 0 | L33: {=SUM(IF(Tabelle1[Raum]=$B33,IF(Tabelle1[Prio]=$L$10,Tabelle1[Pos.Preis])))} -> 10 | M33: {=SUM(IF(Tabelle1[Raum]=B33,Tabelle1[Pos.Preis]))} -> 10
A34: SF | B34: Garage | H34: {=SUM(IF(Tabelle1[Raum]=B34,IF(Tabelle1[Prio]=$H$10,Tabelle1[Pos.Preis])))} -> 2760 | K34: {=SUM(IF(Tabelle1[Raum]=$B34,IF(Tabelle1[Prio]=$K$10,Tabelle1[Pos.Preis])))} -> 0 | L34: {=SUM(IF(Tabelle1[Raum]=$B34,IF(Tabelle1[Prio]=$L$10,Tabelle1[Pos.Preis])))} -> 0 | M34: {=SUM(IF(Tabelle1[Raum]=B34,Tabelle1[Pos.Preis]))} -> 2760
A35: SF | B35: Balkon | H35: {=SUM(IF(Tabelle1[Raum]=B35,IF(Tabelle1[Prio]=$H$10,Tabelle1[Pos.Preis])))} -> 0 | K35: {=SUM(IF(Tabelle1[Raum]=$B35,IF(Tabelle1[Prio]=$K$10,Tabelle1[Pos.Preis])))} -> 0 | L35: {=SUM(IF(Tabelle1[Raum]=$B35,IF(Tabelle1[Prio]=$L$10,Tabelle1[Pos.Preis])))} -> 2 | M35: {=SUM(IF(Tabelle1[Raum]=B35,Tabelle1[Pos.Preis]))} -> 2
A36: SF | B36: Terrasse | H36: {=SUM(IF(Tabelle1[Raum]=B36,IF(Tabelle1[Prio]=$H$10,Tabelle1[Pos.Preis])))} -> 0 | K36: {=SUM(IF(Tabelle1[Raum]=$B36,IF(Tabelle1[Prio]=$K$10,Tabelle1[Pos.Preis])))} -> 0 | L36: {=SUM(IF(Tabelle1[Raum]=$B36,IF(Tabelle1[Prio]=$L$10,Tabelle1[Pos.Preis])))} -> 0 | M36: {=SUM(IF(Tabelle1[Raum]=B36,Tabelle1[Pos.Preis]))} -> 0
B37: Gesamt | H37: =SUM(H11:H36) -> 32800.81 | K37: =SUM(K11:K36) -> 380 | L37: =SUM(L11:L36) -> 490.3 | M37: =SUM(M11:M36) -> 33671.11
B38: =Flächen!$G$34 -> 322.35 | M38: =M37/B38 -> 104.45513
A40: PosNr | B40: Prio | C40: Ebene | D40: Raum | E40: Gewerk | F40: Anz. | G40: EH | H40: Position | I40: Beschreibung | J40: Zeit | K40: EH-Arbeit | L40: Arbeit | M40: EH-Material2 | N40: Material | O40: Pos.Preis
A41: 2 | B41: - | F41: Teichzimmer
A42: 2_1 | B42: Hoch | C42: EG | D42: Teichzimmer | E42: BAUMEISTER | F42: =Flächen!F11 -> 12.21 | G42: m² | H42: Decke GKP | I42: 9,5 mm | J42: 2 | K42: 20 | L42: =Tabelle1[[#This Row],[Anz.]]*Tabelle1[[#This Row],[EH-Arbeit]] -> 244.2 | M42: 5 | N42: =Tabelle1[[#This Row],[Anz.]]+Tabelle1[[#This Row],[EH-Material2]] -> 17.21 | O42: =(Tabelle1[[#This Row],[EH-Material2]]+Tabelle1[[#This Row],[EH-Arbeit]])*Tabelle1[[#This Row],[Anz.]] -> 305.25
A43: 2_4 | B43: Hoch | C43: EG | D43: Teichzimmer | E43: ELEKTRO | F43: 1 | G43: Stk. | H43: Beleuchtung | I43: Deckenlicht - Fassung | J43: 0.25 | K43: 5 | L43: =Tabelle1[[#This Row],[Anz.]]*Tabelle1[[#This Row],[EH-Arbeit]] -> 5 | M43: 6 | N43: =Tabelle1[[#This Row],[Anz.]]+Tabelle1[[#This Row],[EH-Material2]] -> 7 | O43: =(Tabelle1[[#This Row],[EH-Material2]]+Tabelle1[[#This Row],[EH-Arbeit]])*Tabelle1[[#This Row],[Anz.]] -> 11
A44: 2_5 | B44: Hoch | C44: EG | D44: Teichzimmer | E44: MALER | F44: 1 | G44: Stk. | H44: Heizkörper lackieren | I44: weiss | J44: 0.25 | K44: 23 | L44: =Tabelle1[[#This Row],[Anz.]]*Tabelle1[[#This Row],[EH-Arbeit]] -> 23 | M44: 12 | N44: =Tabelle1[[#This Row],[Anz.]]+Tabelle1[[#This Row],[EH-Material2]] -> 13 | O44: =(Tabelle1[[#This Row],[EH-Material2]]+Tabelle1[[#This Row],[EH-Arbeit]])*Tabelle1[[#This Row],[Anz.]] -> 35
A45: 2_6 | B45: Hoch | C45: EG | D45: Teichzimmer | E45: MALER | F45: =Flächen!F11 -> 12.21 | G45: m² | H45: Spachteln | I45: Klimaglätte | J45: 1.5 | K45: 35 | L45: =Tabelle1[[#This Row],[Anz.]]*Tabelle1[[#This Row],[EH-Arbeit]] -> 427.35 | M45: 3 | N45: =Tabelle1[[#This Row],[Anz.]]+Tabelle1[[#This Row],[EH-Material2]] -> 15.21 | O45: =(Tabelle1[[#This Row],[EH-Material2]]+Tabelle1[[#This Row],[EH-Arbeit]])*Tabelle1[[#This Row],[Anz.]] -> 463.98
A46: 2_7 | B46: Hoch | C46: EG | D46: Teichzimmer | E46: ELEKTRO | F46: =Flächen!F11 -> 12.21 | G46: m² | H46: Rohinstallation | I46: Kabel u. UP - Dosen | J46: 0.25 | K46: 6 | L46: =Tabelle1[[#This Row],[Anz.]]*Tabelle1[[#This Row],[EH-Arbeit]] -> 73.26 | M46: 4 | N46: =Tabelle1[[#This Row],[Anz.]]+Tabelle1[[#This Row],[EH-Material2]] -> 16.21 | O46: =(Tabelle1[[#This Row],[EH-Material2]]+Tabelle1[[#This Row],[EH-Arbeit]])*Tabelle1[[#This Row],[Anz.]] -> 122.1
...

Sheet Übersicht
A1: ÜBERSICHT
A5: BAUKOSTEN
B6: Position | E6: erledigt | I6: offen | L6: Gesamt
B7: =Wohnfläche!$A$1 -> WOHNFLÄCHEN | L7: =Wohnfläche!$G$1 -> 36797.4
B8: =Keller!$A$1 -> KELLER | E8: =Keller!$L$7 -> 0.85397978 | I8: =Keller!$L$17 -> 655 | L8: =Keller!$L$21 -> 4485.68
B9: =Terrasse!$A$1 -> TERRASSE | E9: =Terrasse!$Q$6 -> 1 | I9: =Terrasse!$Q$16 -> 0 | L9: =Terrasse!$Q$20 -> 13618.41
B10: =Pergola!$A$1 -> PERGOLA | E10: =Pergola!$Q$6 -> 0.7375932 | I10: =Pergola!$Q$16 -> 1300 | L10: =Pergola!$Q$20 -> 4954.14
B12: GESAMT | L12: =SUM(L7:L11) -> 59855.63

Sheet Wohnfläche
A1: WOHNFLÄCHEN | F1: =G1/Flächen!$G$37 -> 173.62997 | G1: =SUM(G2:G153) -> 36797.4
A2: Abbruch | B2: Entsorgung, Entrümpelung | F2: =G2/Flächen!$G$37 -> 2.6263389 | G2: =SUM(F4:F9) -> 556.6
B3: Rech-Datum | C3: Beschreibung | D3: netto | E3: Ust | F3: brutto
B4: 42760 | C4: AEVG | D4: =F4/(1+E4) -> 3.3333333 | E4: 0.2 | F4: 4
B5: 42768 | C5: AEVG | D5: =F5/(1+E5) -> 25.833333 | E5: 0.2 | F5: 31
B6: 42766 | C6: Saubermacher | D6: =F6/(1+E6) -> 434.66667 | E6: 0.2 | F6: 521.6
D7: =F7/(1+E7) -> 0 | E7: 0.2 | F7: 0
D8: =F8/(1+E8) -> 0 | E8: 0.2 | F8: 0
D9: =F9/(1+E9) -> 0 | E9: 0.2 | F9: 0
A10: Elektro | B10: Elektro Neubauer | F10: =G10/Flächen!$G$37 -> 29.059123 | G10: =SUM(F12:F17) -> 6158.5
B11: Rech-Datum | C11: Beschreibung | D11: netto | E11: Ust | F11: brutto
B12: 42779 | C12: Schalter u Stecker | D12: =F12/(1+E12) -> 1011.6667 | E12: 0.2 | F12: 1214
B13: 42779 | C13: Mehrkosten | D13: =F13/(1+E13) -> 1510.8333 | E13: 0.2 | F13: 1813
B14: 42786 | C14: Mehrkosten | D14: =F14/(1+E14) -> 2469.5833 | E14: 0.2 | F14: 2963.5
B15: 42753 | C15: Solarregler | D15: =F15/(1+E15) -> 140 | E15: 0.2 | F15: 168
D16: =F16/(1+E16) -> 0 | E16: 0.2 | F16: 0
D17: =F17/(1+E17) -> 0 | E17: 0.2 | F17: 0
A18: Boden | B18: Schagerl | F18: =G18/Flächen!$G$37 -> 30.684188 | G18: =SUM(F20:F28) -> 6502.9
B19: Rech-Datum | C19: Beschreibung | D19: netto | E19: Ust | F19: brutto
B20: 42725 | C20: Wohnzimmerboden | D20: =F20/(1+E20) -> 2837.25 | E20: 0.2 | F20: 3404.7
B21: 42738 | C21: Wohnzimmerboden | D21: =F21/(1+E21) -> 1907.5 | E21: 0.2 | F21: 2289
B22: 42738 | C22: Sesselleisten | D22: =F22/(1+E22) -> 250 | E22: 0.2 | F22: 300
B23: 42740 | C23: Sesselleisten | D23: =F23/(1+E23) -> 91.666667 | E23: 0.2 | F23: 110
B24: 42751 | C24: Sesselleisten | D24: =F24/(1+E24) -> 29.5 | E24: 0.2 | F24: 35.4
B25: 42751 | C25: Vinyl | D25: =F25/(1+E25) -> 303.16667 | E25: 0.2 | F25: 363.8
D26: =F26/(1+E26) -> 0 | E26: 0.2 | F26: 0
D27: =F27/(1+E27) -> 0 | E27: 0.2 | F27: 0
D28: =F28/(1+E28) -> 0 | E28: 0.2 | F28: 0
A29: Heizung | B29: Installateur | F29: =G29/Flächen!$G$37 -> 6.5785873 | G29: =SUM(F31:F35) -> 1394.2
B30: Rech-Datum | C30: Beschreibung | D30: netto | E30: Ust | F30: brutto
B31: 42753 | C31: Heizungsanlage | D31: =F31/(1+E31) -> 776 | E31: 0.2 | F31: 931.2
B32: 42786 | C32: Heizungsanlage-Regler | D32: =F32/(1+E32) -> 385.83333 | E32: 0.2 | F32: 463
D33: =F33/(1+E33) -> 0 | E33: 0.2 | F33: 0
D34: =F34/(1+E34) -> 0 | E34: 0.2 | F34: 0
D35: =F35/(1+E35) -> 0 | E35: 0.2 | F35: 0
A36: Sanitär Installation | B36: TFHaustec | F36: =G36/Flächen!$G$37 -> 3.3926296 | G36: =SUM(F38:F41) -> 719
B37: Rech-Datum | C37: Beschreibung | D37: netto | E37: Ust | F37: brutto
B38: 42753 | C38: Rohinstall | D38: =F38/(1+E38) -> 599.16667 | E38: 0.2 | F38: 719
D39: =F39/(1+E39) -> 0 | E39: 0.2 | F39: 0
D40: =F40/(1+E40) -> 0 | E40: 0.2 | F40: 0
...

Sheet Keller
A1: KELLER
A4: ALLGEMEIN | D4: Fläche | L4: =Flächen!$G$23 -> 73.36
D5: Material | L5: =SUMIF(Tabelle15[Art],D5,Tabelle15[kg gesamt]) -> 1705
D6: Arbeit | L6: =SUMIF(Tabelle15[Art],D6,Tabelle15[Az]) -> 90
D7: Erledigt | L7: =L13/L21 -> 0.85397978
D8: Offen | L8: =L17/L21 -> 0.14602022
A10: KOSTEN
B11: erledigt | D11: Material | L11: {=SUM(IF(Tabelle15[Status]=$B11,IF(Tabelle15[Art]=D$11,Tabelle15[Preis, brutto])))} -> 1015.89
D12: Arbeit | L12: {=SUM(IF(Tabelle15[Status]=$B11,IF(Tabelle15[Art]=D$12,Tabelle15[Preis, brutto])))} -> 2814.79
D13: Gesamt | L13: =SUM(L11:L12) -> 3830.68
B15: offen | D15: Material | L15: {=SUM(IF(Tabelle15[Status]=$B15,IF(Tabelle15[Art]=D$15,Tabelle15[Preis, brutto])))} -> 200
D16: Arbeit | L16: {=SUM(IF(Tabelle15[Status]=$B15,IF(Tabelle15[Art]=D$16,Tabelle15[Preis, brutto])))} -> 455
D17: Gesamt | L17: =SUM(L15:L16) -> 655
D19: Material | L19: =SUMIF(Tabelle15[Art],D19,Tabelle15[Preis, brutto]) -> 1215.89
D20: Arbeit | L20: =SUMIF(Tabelle15[Art],D20,Tabelle15[Preis, brutto]) -> 3269.79
D21: Gesamt | L21: =SUM(L19:L20) -> 4485.68
A24: KELLER | M24: =SUM(L26:L81) -> 4485.68
A25: Datum | B25: Az | C25: EH | D25: Position | E25: Kostenstelle | F25: Art | G25: Gebinde | H25: kg gesamt | I25: Status | J25: Bezahlung | K25: Pos.Preis | L25: Preis, brutto
A26: 43105 | B26: 4 | C26: h | D26: Verputzen, … | E26: uh | F26: Arbeit | I26: erledigt | K26: 35 | L26: =B26*K26 -> 140
A27: 43108 | B27: 1 | C27: Sk. | D27: Klimaputz | E27: Hornbach | F27: Material | G27: 25 | H27: =Tabelle15[[#This Row],[Az]]*Tabelle15[[#This Row],[Gebinde]] -> 25 | I27: erledigt | J27: Projektkarte | K27: 8.48 | L27: =B27*K27 -> 8.48
A28: 43108 | B28: 1 | C28: Sk. | D28: Klimaglätte | E28: Hornbach | F28: Material | G28: 25 | H28: =Tabelle15[[#This Row],[Az]]*Tabelle15[[#This Row],[Gebinde]] -> 25 | I28: erledigt | J28: Projektkarte | K28: 13.89 | L28: =B28*K28 -> 13.89
A29: 43108 | B29: 1 | C29: Sk. | D29: Klebespachtel | E29: Hornbach | F29: Material | G29: 25 | H29: =Tabelle15[[#This Row],[Az]]*Tabelle15[[#This Row],[Gebinde]] -> 25 | I29: erledigt | J29: Projektkarte | K29: 10.89 | L29: =B29*K29 -> 10.89
A30: 43108 | B30: 1 | C30: Sk. | D30: Feinputz | E30: Hornbach | F30: Material | G30: 25 | H30: =Tabelle15[[#This Row],[Az]]*Tabelle15[[#This Row],[Gebinde]] -> 25 | I30: erledigt | J30: Projektkarte | K30: 12.84 | L30: =B30*K30 -> 12.84
A31: 43108 | B31: 3 | C31: Sk. | D31: Kalkzementputz | E31: Hornbach | F31: Material | G31: 40 | H31: =Tabelle15[[#This Row],[Az]]*Tabelle15[[#This Row],[Gebinde]] -> 120 | I31: erledigt | J31: Projektkarte | K31: 3.09 | L31: =B31*K31 -> 9.27
A32: 43108 | B32: 1 | C32: Geb | D32: Abdichtung | E32: Hornbach | F32: Material | I32: erledigt | J32: Projektkarte | K32: 29.95 | L32: =B32*K32 -> 29.95
A33: 43108 | B33: 1 | C33: Sk. | D33: Zement | E33: Hornbach | F33: Material | G33: 25 | H33: =Tabelle15[[#This Row],[Az]]*Tabelle15[[#This Row],[Gebinde]] -> 25 | I33: erledigt | J33: Projektkarte | K33: 4.9 | L33: =B33*K33 -> 4.9
A34: 43108 | B34: 1 | C34: Pa. | D34: Kleinmaterial | E34: Hornbach | F34: Material | I34: erledigt | J34: Projektkarte | K34: 63.04 | L34: =B34*K34 -> 63.04
A35: 43108 | B35: 13 | C35: h | D35: Verputzen, … | E35: uh | F35: Arbeit | I35: erledigt | K35: 35 | L35: =B35*K35 -> 455
A36: 43109 | B36: 9 | C36: h | D36: Spachteln | E36: uh | F36: Arbeit | I36: erledigt | K36: 35 | L36: =B36*K36 -> 315
A37: 43111 | B37: 1 | C37: Sk. | D37: Klebespachtel | E37: Hornbach | F37: Material | G37: 25 | H37: =Tabelle15[[#This Row],[Az]]*Tabelle15[[#This Row],[Gebinde]] -> 25 | I37: erledigt | J37: Projektkarte | K37: 10.89 | L37: =B37*K37 -> 10.89
A38: 43111 | B38: 4 | C38: Sk. | D38: Kalkzementputz | E38: Hornbach | F38: Material | G38: 40 | H38: =Tabelle15[[#This Row],[Az]]*Tabelle15[[#This Row],[Gebinde]] -> 160 | I38: erledigt | J38: Projektkarte | K38: 3.09 | L38: =B38*K38 -> 12.36
A39: 43111 | B39: 1 | C39: Sk. | D39: Klimaglätte | E39: Hornbach | F39: Material | G39: 25 | H39: =Tabelle15[[#This Row],[Az]]*Tabelle15[[#This Row],[Gebinde]] -> 25 | I39: erledigt | J39: Projektkarte | K39: 13.89 | L39: =B39*K39 -> 13.89
A40: 43111 | B40: 3 | C40: Sk. | D40: Klimaputz | E40: Hornbach | F40: Material | G40: 25 | H40: =Tabelle15[[#This Row],[Az]]*Tabelle15[[#This Row],[Gebinde]] -> 75 | I40: erledigt | J40: Projektkarte | K40: 8.48 | L40: =B40*K40 -> 25.44
A41: 43111 | B41: 1 | C41: Pa. | D41: Kleinmaterial | E41: Hornbach | F41: Material | I41: erledigt | J41: Projektkarte | K41: 58.19 | L41: =B41*K41 -> 58.19
A42: 43111 | B42: 12 | C42: h | D42: Verputzen, … | E42: uh | F42: Arbeit | I42: erledigt | K42: 35 | L42: =B42*K42 -> 420
A43: 43112 | B43: 10 | C43: h | D43: Verputzen, Boden | E43: uh | F43: Arbeit | I43: erledigt | K43: 35 | L43: =B43*K43 -> 350
A44: 43113 | B44: 3 | C44: Sk. | D44: Klimaputz | E44: Hornbach | F44: Material | G44: 25 | H44: =Tabelle15[[#This Row],[Az]]*Tabelle15[[#This Row],[Gebinde]] -> 75 | I44: erledigt | J44: Projektkarte | K44: 4 | L44: =B44*K44 -> 12
A45: 43113 | B45: 1 | C45: Sk. | D45: Klimaputz | E45: Hornbach | F45: Material | G45: 25 | H45: =Tabelle15[[#This Row],[Az]]*Tabelle15[[#This Row],[Gebinde]] -> 25 | I45: erledigt | J45: Projektkarte | K45: 8.48 | L45: =B45*K45 -> 8.48
A46: 43113 | B46: 2 | C46: Sk. | D46: Klimaspachtel | E46: Hornbach | F46: Material | G46: 25 | H46: =Tabelle15[[#This Row],[Az]]*Tabelle15[[#This Row],[Gebinde]] -> 50 | I46: erledigt | J46: Projektkarte | K46: 16.95 | L46: =B46*K46 -> 33.9
A47: 43113 | B47: 2 | C47: Sk. | D47: Klebespachtel | E47: Hornbach | F47: Material | G47: 25 | H47: =Tabelle15[[#This Row],[Az]]*Tabelle15[[#This Row],[Gebinde]] -> 50 | I47: erledigt | J47: Projektkarte | K47: 10.89 | L47: =B47*K47 -> 21.78
...

Sheet Terrasse
A1: TERRASSE
A3: ALLGEMEIN | D3: Fläche | P3: =Q20/Q3 -> 170.23012 | Q3: 80
D5: Arbeit | Q5: =SUMIF(Tabelle157[Art],D5,Tabelle157[Az]) -> 221.4
D6: Erledigt | Q6: =Q12/Q20 -> 1
D7: Offen | Q7: =Q16/Q20 -> 0
A9: KOSTEN
B10: erledigt | D10: Material | Q10: {=SUM(IF(Tabelle157[Status]=$B10,IF(Tabelle157[Art]=D$10,Tabelle157[Preis, brutto])))} -> 5866.91
D11: Arbeit | Q11: {=SUM(IF(Tabelle157[Status]=$B10,IF(Tabelle157[Art]=D$11,Tabelle157[Preis, brutto])))} -> 7751.5
D12: Gesamt | Q12: =SUM(Q10:Q11) -> 13618.41
B14: offen | D14: Material | Q14: {=SUM(IF(Tabelle157[Status]=$B14,IF(Tabelle157[Art]=D$14,Tabelle157[Preis, brutto])))} -> 0
D15: Arbeit | Q15: {=SUM(IF(Tabelle157[Status]=$B14,IF(Tabelle157[Art]=D$15,Tabelle157[Preis, brutto])))} -> 0
D16: Gesamt | Q16: =SUM(Q14:Q15) -> 0
D18: Material | Q18: =SUMIF(Tabelle157[Art],D18,Tabelle157[Preis, brutto]) -> 5866.91
D19: Arbeit | Q19: =SUMIF(Tabelle157[Art],D19,Tabelle157[Preis, brutto]) -> 7751.5
D20: Terrasse | Q20: =SUM(Q18:Q19) -> 13618.41
A23: MATERIALLISTE | R23: =SUM(Q25:Q92) -> 13618.41
A24: Datum | B24: Az | C24: EH | D24: Position | E24: Kostenstelle | F24: sonstiges | G24: Art | H24: Breite | I24: Höhe | J24: Länge | K24: Volumen | L24: lfm | M24: Gebinde | N24: kg gesamt | O24: Status | P24: Pos.Preis | Q24: Preis, brutto
A25: 43140 | B25: 1 | C25: Pa. | D25: Kleinmaterial | G25: Material | O25: erledigt | P25: 38.45 | Q25: =B25*P25 -> 38.45
A26: 43152 | B26: 500 | C26: kg | D26: Baustellenabfälle | E26: AEVG | G26: Material | O26: erledigt | P26: 0.068 | Q26: =B26*P26 -> 34
A27: 43152 | B27: 40 | C27: Stk. | D27: Estrich | E27: Bauhaus | G27: Material | O27: erledigt | P27: 3.1 | Q27: =B27*P27 -> 124
A28: 43153 | B28: 1 | C28: Pa. | D28: Kleinmaterial | E28: Hornbach | G28: Material | O28: erledigt | P28: 45.49 | Q28: =B28*P28 -> 45.49
A29: 43169 | B29: 1 | C29: Sk. | D29: Klebespachtel | E29: Hornbach | G29: Material | O29: erledigt | P29: 12.99 | Q29: =B29*P29 -> 12.99
A30: 43171 | B30: 1 | C30: Stk. | D30: Ausgleichspad / Balkenunterlage | E30: Hornbach | G30: Material | O30: erledigt | P30: 6.95 | Q30: =B30*P30 -> 6.95
A31: 43171 | B31: 1 | C31: Pkg. | D31: Abdeckband | E31: Hornbach | G31: Material | O31: erledigt | P31: 29.9 | Q31: =B31*P31 -> 29.9
A32: 43171 | B32: 1 | C32: Pa. | D32: Kleinmaterial | E32: Hornbach | G32: Material | O32: erledigt | P32: 34 | Q32: =B32*P32 -> 34
A33: 43190 | B33: 111.25 | C33: m² | D33: Terrassenboden Lärchenholz 36 mm | G33: Material | O33: erledigt | P33: 25.617978 | Q33: =B33*P33 -> 2850
A34: 43190 | B34: 1 | C34: Pa. | D34: Lieferung | G34: Material | O34: erledigt | P34: 70 | Q34: =B34*P34 -> 70
A35: 43173 | B35: 150 | C35: lfm | D35: Konstruktionsvollholz 8/12 | E35: Bauhaus | G35: Material | O35: erledigt | P35: 5 | Q35: =B35*P35 -> 750
A36: 43173 | B36: 10 | C36: Stk. | D36: Trockenbeton | E36: Bauhaus | G36: Material | O36: erledigt | P36: 4.99 | Q36: =B36*P36 -> 49.9
A37: 43173 | B37: 6 | C37: lfm | D37: Winkelprofil | E37: Bauhaus | G37: Material | O37: erledigt | P37: 9.9 | Q37: =B37*P37 -> 59.4
A38: 43173 | B38: 30 | C38: lfm | D38: Flachstahl | E38: Bauhaus | G38: Material | O38: erledigt | P38: 6 | Q38: =B38*P38 -> 180
A39: 43173 | B39: 1 | C39: Pa. | D39: Transporter Leihgebühr | E39: Bauhaus | G39: Material | O39: erledigt | P39: 9 | Q39: =B39*P39 -> 9
A40: 43173 | B40: 1 | C40: Pa. | D40: XPS Platte | E40: Bauhaus | G40: Material | O40: erledigt | P40: 13.35 | Q40: =B40*P40 -> 13.35
A41: 43175 | B41: 6 | C41: Stk. | D41: Schalungssteine | E41: Bauhaus | G41: Material | O41: erledigt | P41: 1.79 | Q41: =B41*P41 -> 10.74
A42: 43180 | B42: 2 | C42: Pkg. | D42: Abdeckband | E42: Hornbach | G42: Material | O42: erledigt | P42: 29.9 | Q42: =B42*P42 -> 59.8
A43: 43180 | B43: 2 | C43: Stk. | D43: Ausgleichspad / Balkenunterlage | E43: Hornbach | G43: Material | O43: erledigt | P43: 6.95 | Q43: =B43*P43 -> 13.9
A44: 43180 | B44: 1 | C44: Pkg. | D44: Terrassenschrauben | E44: Hornbach | G44: Material | O44: erledigt | P44: 15.5 | Q44: =B44*P44 -> 15.5
A45: 43180 | B45: 1 | C45: Pa. | D45: Kleinmaterial | E45: Hornbach | G45: Material | O45: erledigt | P45: 15 | Q45: =B45*P45 -> 15
A46: 43182 | B46: 2000 | C46: Stk. | D46: Terrassenschrauben | E46: Amazon | G46: Material | O46: erledigt | P46: 0.05451 | Q46: =B46*P46 -> 109.02
... A91: 43207 | B91: 10.1 | C91: h | D91: Terrasse | E91: uh | G91: Arbeit | O91: erledigt | P91: 35 | Q91: =B91*P91 -> 353.5
...

Sheet Pergola
A1: PERGOLA
A3: ALLGEMEIN | D3: Fläche | Q3: 15
D5: Arbeit | Q5: =SUMIF(Tabelle1576[Art],D5,Tabelle1576[Az]) -> 69.7
D6: Erledigt | Q6: =Q12/Q20 -> 0.7375932
D7: Offen | Q7: =Q16/Q20 -> 0.2624068
A9: KOSTEN
B10: erledigt | D10: Material | Q10: {=SUM(IF(Tabelle1576[Status]=$B10,IF(Tabelle1576[Art]=D$10,Tabelle1576[Preis, brutto])))} -> 1914.64
D11: Arbeit | Q11: {=SUM(IF(Tabelle1576[Status]=$B10,IF(Tabelle1576[Art]=D$11,Tabelle1576[Preis, brutto])))} -> 1739.5
D12: Gesamt | Q12: =SUM(Q10:Q11) -> 3654.14
B14: offen | D14: Material | Q14: {=SUM(IF(Tabelle1576[Status]=$B14,IF(Tabelle1576[Art]=D$14,Tabelle1576[Preis, brutto])))} -> 600
D15: Arbeit | Q15: {=SUM(IF(Tabelle1576[Status]=$B14,IF(Tabelle1576[Art]=D$15,Tabelle1576[Preis, brutto])))} -> 700
D16: Gesamt | Q16: =SUM(Q14:Q15) -> 1300
D18: Material | Q18: =SUMIF(Tabelle1576[Art],D18,Tabelle1576[Preis, brutto]) -> 2514.64
D19: Arbeit | Q19: =SUMIF(Tabelle1576[Art],D19,Tabelle1576[Preis, brutto]) -> 2439.5
D20: Gesamt | Q20: =SUM(Q18:Q19) -> 4954.14
A22: MATERIALLISTE | R22: =SUM(Q24:Q54) -> 4954.14
A23: Datum | B23: Az | C23: EH | D23: Position | E23: Kostenstelle | F23: sonstiges | G23: Art | H23: Breite | I23: Höhe | J23: Länge | K23: Volumen | L23: lfm | M23: Gebinde | N23: kg gesamt | O23: Status | P23: Pos.Preis | Q23: Preis, brutto
A24: 43173 | B24: 10 | C24: Stk. | D24: Trockenbeton | E24: Bauhaus | G24: Material | O24: erledigt | P24: 4.99 | Q24: =B24*P24 -> 49.9
A25: 43173 | B25: 6 | C25: lfm | D25: Winkelprofil | E25: Bauhaus | G25: Material | O25: erledigt | P25: 9.9 | Q25: =B25*P25 -> 59.4
A26: 43185 | B26: 1 | C26: Pa. | D26: Kleinmaterial | G26: Material | O26: erledigt | P26: 21.3 | Q26: =B26*P26 -> 21.3
A27: 43193 | B27: 1 | C27: Pa. | D27: Kleinmaterial | E27: Hornbach | G27: Material | O27: erledigt | P27: 226.52 | Q27: =B27*P27 -> 226.52
A28: 43195 | B28: 1 | C28: Pa. | D28: Kleinmaterial | G28: Material | O28: erledigt | P28: 53.75 | Q28: =B28*P28 -> 53.75
A29: 43195 | B29: 1 | C29: Pa. | D29: Kleinmaterial | E29: Hornbach | G29: Material | O29: erledigt | P29: 100.8 | Q29: =B29*P29 -> 100.8
A30: 43196 | B30: 5 | C30: Stk. | D30: Trockenbeton | E30: Bauhaus | G30: Material | O30: erledigt | P30: 4.99 | Q30: =B30*P30 -> 24.95
A31: 43196 | B31: 5 | C31: Stk. | D31: Estrich | E31: Bauhaus | G31: Material | O31: erledigt | P31: 3.09 | Q31: =B31*P31 -> 15.45
A32: 43196 | B32: 4 | C32: Stk. | D32: Brett sägerauh | E32: Bauhaus | G32: Material | O32: erledigt | P32: 4.99 | Q32: =B32*P32 -> 19.96
A33: 43196 | B33: 10 | C33: Stk. | D33: Leimbinder 10/10 Steher | E33: Bauhaus | F33: Fichte | G33: Material | H33: 10 | I33: 10 | J33: 280 | L33: =(Tabelle1576[[#This Row],[Länge]]*Tabelle1576[[#This Row],[Az]])/100 -> 28 | O33: erledigt | P33: 7.6 | Q33: =L33*P33 -> 212.8
A34: 43196 | B34: 1 | C34: Stk. | D34: Leimbinder 10/10 Steher | E34: Bauhaus | F34: Fichte | G34: Material | H34: 10 | I34: 10 | J34: 500 | L34: =(Tabelle1576[[#This Row],[Länge]]*Tabelle1576[[#This Row],[Az]])/100 -> 5 | O34: erledigt | P34: 7.6 | Q34: =L34*P34 -> 38
A35: 43196 | B35: 7 | C35: Stk. | D35: Leimbinder 8/16 Tram | E35: Bauhaus | F35: Fichte | G35: Material | H35: 10 | I35: 16 | J35: 280 | L35: =(Tabelle1576[[#This Row],[Länge]]*Tabelle1576[[#This Row],[Az]])/100 -> 19.6 | O35: erledigt | P35: 9.8 | Q35: =L35*P35 -> 192.08
A36: 43196 | B36: 1 | C36: Stk. | D36: Leimbinder 10/20 Überzug | E36: Bauhaus | F36: Fichte | G36: Material | H36: 10 | I36: 20 | J36: 500 | L36: =(Tabelle1576[[#This Row],[Länge]]*Tabelle1576[[#This Row],[Az]])/100 -> 5 | O36: erledigt | P36: 15.3 | Q36: =L36*P36*Tabelle1576[[#This Row],[Az]] -> 76.5
A37: 43199 | B37: 1 | C37: Pa. | D37: Kleinmaterial | E37: Hornbach | G37: Material | O37: erledigt | P37: 150 | Q37: =B37*P37 -> 150
A38: 43203 | B38: 8 | C38: Stk. | D38: Hirnholz - Einhängeverbinder | E38: derbeschlagsprofi | G38: Material | O38: erledigt | P38: 17.49 | Q38: =Tabelle1576[[#This Row],[Pos.Preis]]*Tabelle1576[[#This Row],[Az]] -> 139.92
A39: 43173 | B39: 1 | C39: Pa. | D39: Transporter Leihgebühr | E39: Bauhaus | G39: Material | O39: erledigt | P39: 21 | Q39: =B39*P39 -> 21
A40: 43196 | B40: 4 | C40: Stk. | D40: Trockenbeton | E40: Hornbach | G40: Material | O40: erledigt | P40: 4.99 | Q40: =B40*P40 -> 19.96
A41: 43213 | B41: 2 | C41: Stk. | D41: Leimbinder 10/10 Steher | E41: Bauhaus | F41: Fichte | G41: Material | H41: 10 | I41: 10 | J41: 270 | L41: =(Tabelle1576[[#This Row],[Länge]]*Tabelle1576[[#This Row],[Az]])/100 -> 5.4 | O41: erledigt | P41: 7.6 | Q41: =L41*P41 -> 41.04
A42: 43213 | B42: 1 | C42: Pa. | D42: Kleinmaterial | E42: Hornbach | G42: Material | O42: erledigt | P42: 111.33 | Q42: =B42*P42 -> 111.33
A43: 43214 | B43: 2 | C43: Stk. | D43: Konstruktionslatten Fi/Ta | E43: Bauhaus | F43: Fichte | G43: Material | O43: erledigt | P43: 5.5 | Q43: =B43*P43 -> 11
A44: 43214 | B44: 1 | C44: Pa. | D44: Kleinmaterial | E44: Hornbach | G44: Material | O44: erledigt | P44: 83.62 | Q44: =B44*P44 -> 83.62
A45: 43216 | B45: 8 | C45: Stk. | D45: Hirnholz - Einhängeverbinder | E45: derbeschlagsprofi | G45: Material | O45: erledigt | P45: 17.49 | Q45: =Tabelle1576[[#This Row],[Pos.Preis]]*Tabelle1576[[#This Row],[Az]] -> 139.92
A46: 43218 | B46: 1 | C46: Pa. | D46: Kleinmaterial | E46: Bauhaus | G46: Material | O46: erledigt | P46: 50 | Q46: =B46*P46 -> 50
...

Sheet Garten
A1: PERGOLA
A3: ALLGEMEIN | D3: Fläche | Q3: 15
D5: Arbeit | Q5: =SUMIF(Tabelle15768[Art],D5,Tabelle15768[Az]) -> 0
D6: Erledigt | Q6: =Q12/Q20 -> 1
D7: Offen | Q7: =Q16/Q20 -> 0
A9: KOSTEN
B10: erledigt | D10: Material | Q10: {=SUM(IF(Tabelle15768[Status]=$B10,IF(Tabelle15768[Art]=D$10,Tabelle15768[Preis, brutto])))} -> 120.26
D11: Arbeit | Q11: {=SUM(IF(Tabelle15768[Status]=$B10,IF(Tabelle15768[Art]=D$11,Tabelle15768[Preis, brutto])))} -> 0
D12: Gesamt | Q12: =SUM(Q10:Q11) -> 120.26
B14: offen | D14: Material | Q14: {=SUM(IF(Tabelle15768[Status]=$B14,IF(Tabelle15768[Art]=D$14,Tabelle15768[Preis, brutto])))} -> 0
D15: Arbeit | Q15: {=SUM(IF(Tabelle15768[Status]=$B14,IF(Tabelle15768[Art]=D$15,Tabelle15768[Preis, brutto])))} -> 0
D16: Gesamt | Q16: =SUM(Q14:Q15) -> 0
D18: Material | Q18: =SUMIF(Tabelle15768[Art],D18,Tabelle15768[Preis, brutto]) -> 120.26
D19: Arbeit | Q19: =SUMIF(Tabelle15768[Art],D19,Tabelle15768[Preis, brutto]) -> 0
D20: Gesamt | Q20: =SUM(Q18:Q19) -> 120.26
A22: MATERIALLISTE | R22: =SUM(Q24:Q27) -> 120.26
A23: Datum | B23: Az | C23: EH | D23: Position | E23: Kostenstelle | F23: sonstiges | G23: Art | H23: Breite | I23: Höhe | J23: Länge | K23: Volumen | L23: lfm | M23: Gebinde | N23: kg gesamt | O23: Status | P23: Pos.Preis | Q23: Preis, brutto
A24: 43196 | B24: 20 | C24: Stk. | D24: Blumenerde | E24: Bauhaus | G24: Material | O24: erledigt | P24: 3.39 | Q24: =B24*P24 -> 67.8
A25: 43199 | B25: 2 | C25: Stk. | D25: Grbrauchtrasen | E25: Hornbach | G25: Material | O25: erledigt | P25: 6.99 | Q25: =B25*P25 -> 13.98
A26: 43199 | B26: 4 | C26: Stk. | D26: Blumenerde 50l | E26: Hornbach | G26: Material | O26: erledigt | P26: 2.75 | Q26: =B26*P26 -> 11
A27: 43214 | B27: 12 | C27: Sk. | D27: Blumenerde | E27: Bauhaus | G27: Material | O27: erledigt | P27: 2.29 | Q27: =B27*P27 -> 27.48
A28: Ergebnis | Q28: =SUBTOTAL(109,Tabelle15768[Preis, brutto]) -> 120.26

Sheet db_Abrechnung
A1: Datum | B1: Anz | C1: EH | D1: Gewerk | E1: Position | F1: Anmerkung | G1: Art | H1: bez/offen | I1: Rech | J1: EH-Preis | K1: Pos.Preis
A2: 42675 | B2: 1 | C2: Pa | D2: Maler | E2: Hornbach | F2: diverses | G2: Material | H2: bezahlt | I2: Thoenen | J2: 168.3 | K2: =Tabelle2[[#This Row],[Anz]]*Tabelle2[[#This Row],[EH-Preis]] -> 168.3
A3: 42680 | B3: 5 | C3: h | D3: Maler | E3: uh | F3: Arbeit | G3: Arbeit | H3: bezahlt | I3: uh bezahlt | J3: 25 | K3: =Tabelle2[[#This Row],[Anz]]*Tabelle2[[#This Row],[EH-Preis]] -> 125
A4: 42682 | B4: 1 | C4: Pa | D4: Maler | E4: Hornbach | F4: ls | G4: Material | H4: bezahlt | I4: Thoenen | J4: 73 | K4: =Tabelle2[[#This Row],[Anz]]*Tabelle2[[#This Row],[EH-Preis]] -> 73
A5: 42686 | B5: 1 | C5: Pa | D5: Maler | E5: Hornbach | F5: diverses | G5: Material | H5: bezahlt | I5: Thoenen | J5: 7.1 | K5: =Tabelle2[[#This Row],[Anz]]*Tabelle2[[#This Row],[EH-Preis]] -> 7.1
A6: 42686 | B6: 1 | C6: Pa | D6: Maler | E6: Hornbach | F6: diverses | G6: Material | H6: bezahlt | I6: MAD | J6: 20.8 | K6: =Tabelle2[[#This Row],[Anz]]*Tabelle2[[#This Row],[EH-Preis]] -> 20.8
A7: 42688 | B7: 1 | C7: Pa | D7: Maler | E7: Hornbach | F7: diverses | G7: Material | H7: bezahlt | I7: Thoenen | J7: 91.4 | K7: =Tabelle2[[#This Row],[Anz]]*Tabelle2[[#This Row],[EH-Preis]] -> 91.4
A8: 42691 | B8: 1 | C8: Pa | D8: Maler | E8: Hornbach | F8: uh | G8: Material | H8: bezahlt | I8: Room Nr9 | J8: 238.3 | K8: =Tabelle2[[#This Row],[Anz]]*Tabelle2[[#This Row],[EH-Preis]] -> 238.3
A9: 42694 | B9: 1 | C9: Pa | D9: Maler | E9: Hornbach | F9: diverses | G9: Material | H9: bezahlt | I9: Room Nr9 | J9: 174.6 | K9: =Tabelle2[[#This Row],[Anz]]*Tabelle2[[#This Row],[EH-Preis]] -> 174.6
A10: 42700 | B10: 1 | C10: Pa | D10: Baumeister | E10: Obi | F10: diverses | G10: Material | H10: bez | I10: MAD | J10: 57.2 | K10: =Tabelle2[[#This Row],[Anz]]*Tabelle2[[#This Row],[EH-Preis]] -> 57.2
A11: 42702 | B11: 1 | C11: Pa | D11: Baumeister | E11: Hornbach | F11: diverses | G11: Material | H11: bezahlt | I11: Thoenen | J11: 174.6 | K11: =Tabelle2[[#This Row],[Anz]]*Tabelle2[[#This Row],[EH-Preis]] -> 174.6
A12: 42705 | B12: 170 | C12: km | D12: Allgemein | E12: Reisekosten | F12: Benzin, Auto, ... | G12: Material | H12: bez | I12: Room Nr9 | J12: 0.2 | K12: =Tabelle2[[#This Row],[Anz]]*Tabelle2[[#This Row],[EH-Preis]] -> 34
A13: 42705 | B13: 8 | C13: h | D13: Baumeister | E13: Chief | F13: Arbeit | G13: Arbeit | H13: bez | I13: Chief | J13: 15 | K13: =Tabelle2[[#This Row],[Anz]]*Tabelle2[[#This Row],[EH-Preis]] -> 120
... A90: 42751 | B90: 1 | C90: Pa | D90: Boden | E90: Schagerl | F90: Vinyl | G90: Boden | H90: bez | I90: MAD | J90: 363.8 | K90: =Tabelle2[[#This Row],[Anz]]*Tabelle2[[#This Row],[EH-Preis]] -> 363.8
A91: 42751 | B91: 1 | C91: Stk. | D91: Tür | E91: Hornbach | F91: Duschtrennwand | G91: Material | H91: bezahlt | J91: 239 | K91: =Tabelle2[[#This Row],[Anz]]*Tabelle2[[#This Row],[EH-Preis]] -> 239
A92: 42751 | B92: 1 | C92: Pa | D92: Maler | E92: Hornbach | G92: Material | H92: bezahlt | J92: 327.7 | K92: =Tabelle2[[#This Row],[Anz]]*Tabelle2[[#This Row],[EH-Preis]] -> 327.7
A93: 42753 | B93: 15.5 | C93: h | D93: Maler | E93: uh | F93: Arbeit | G93: Arbeit | H93: offen | I93: uh offen | J93: 25 | K93: =Tabelle2[[#This Row],[Anz]]*Tabelle2[[#This Row],[EH-Preis]] -> 387.5
A94: 42753 | B94: 1 | C94: Pa | D94: Maler | E94: Hornbach | G94: Material | H94: bezahlt | J94: 116.5 | K94: =Tabelle2[[#This Row],[Anz]]*Tabelle2[[#This Row],[EH-Preis]] -> 116.5
A95: 42754 | B95: 12 | C95: h | D95: Maler | E95: uh | F95: Arbeit | G95: Arbeit | H95: offen | I95: uh offen | J95: 25 | K95: =Tabelle2[[#This Row],[Anz]]*Tabelle2[[#This Row],[EH-Preis]] -> 300
A96: 42755 | B96: 14.5 | C96: h | D96: Boden | E96: uh | F96: Arbeit | G96: Arbeit | H96: offen | I96: uh offen | J96: 25 | K96: =Tabelle2[[#This Row],[Anz]]*Tabelle2[[#This Row],[EH-Preis]] -> 362.5
A97: 42755 | B97: 1 | C97: Pa | D97: Baumeister | E97: Hornbach | G97: Material | H97: bezahlt | J97: 658 | K97: =Tabelle2[[#This Row],[Anz]]*Tabelle2[[#This Row],[EH-Preis]] -> 658
A98: 42755 | B98: 1 | C98: Pa | D98: Fliesen | E98: Obi | F98: diverses | G98: Material | H98: bez | I98: MAD | J98: 217.6 | K98: =Tabelle2[[#This Row],[Anz]]*Tabelle2[[#This Row],[EH-Preis]] -> 217.6
A99: 42756 | B99: 16 | C99: h | D99: Boden | E99: uh | F99: Arbeit | G99: Arbeit | H99: offen | I99: uh offen | J99: 25 | K99: =Tabelle2[[#This Row],[Anz]]*Tabelle2[[#This Row],[EH-Preis]] -> 400
A100: 42756 | B100: 1 | C100: Pa | D100: Sanitär | E100: Hornbach | G100: Material | H100: bezahlt | J100: 340.4 | K100: =Tabelle2[[#This Row],[Anz]]*Tabelle2[[#This Row],[EH-Preis]] -> 340.4
A101: 42757 | B101: 15 | C101: h | D101: Boden | E101: uh | F101: Arbeit | G101: Arbeit | H101: offen | I101: uh offen | J101: 25 | K101: =Tabelle2[[#This Row],[Anz]]*Tabelle2[[#This Row],[EH-Preis]] -> 375
A102: 42758 | B102: 11.5 | C102: h | D102: Boden | E102: uh | F102: Arbeit | G102: Arbeit | H102: offen | I102: uh offen | J102: 25 | K102: =Tabelle2[[#This Row],[Anz]]*Tabelle2[[#This Row],[EH-Preis]] -> 287.5
A103: 42758 | B103: 1 | C103: Stk. | D103: Heizung | E103: Infrarot Heizkörper | F103: Material | G103: Heizkörper | H103: bez | I103: Manuel | J103: 550 | K103: =Tabelle2[[#This Row],[Anz]]*Tabelle2[[#This Row],[EH-Preis]] -> 550
A104: 42758 | B104: 1 | C104: Pa | D104: Boden | E104: Hornbach | F104: div | G104: Material | H104: bezahlt | I104: Room Nr9 | J104: 166.9 | K104: =Tabelle2[[#This Row],[Anz]]*Tabelle2[[#This Row],[EH-Preis]] -> 166.9
A105: 42759 | B105: 14 | C105: h | D105: Montage | E105: uh | F105: Arbeit | G105: Arbeit | H105: offen | I105: uh offen | J105: 25 | K105: =Tabelle2[[#This Row],[Anz]]*Tabelle2[[#This Row],[EH-Preis]] -> 350
A106: 42759 | B106: 1 | C106: Pa | D106: Baumeister | E106: Hornbach | G106: Material | H106: bezahlt | J106: 917.9 | K106: =Tabelle2[[#This Row],[Anz]]*Tabelle2[[#This Row],[EH-Preis]] -> 917.9
A107: 42759 | B107: 1 | C107: Pa | D107: Boden | E107: Bauhaus | G107: Material | H107: bez | J107: 36.9 | K107: =Tabelle2[[#This Row],[Anz]]*Tabelle2[[#This Row],[EH-Preis]] -> 36.9
A108: 42760 | B108: 13 | C108: h | D108: Montage | E108: uh | F108: Arbeit | G108: Arbeit | H108: offen | I108: uh offen | J108: 25 | K108: =Tabelle2[[#This Row],[Anz]]*Tabelle2[[#This Row],[EH-Preis]] -> 325
A109: 42760 | B109: 1 | C109: Pa | D109: Baumeister | E109: AEVG | G109: Entsorgung | H109: bezahlt | J109: 4 | K109: =Tabelle2[[#This Row],[Anz]]*Tabelle2[[#This Row],[EH-Preis]] -> 4
A110: 42760 | B110: 1 | C110: Pa | D110: Boden | E110: Bauhaus | G110: Material | H110: bez | J110: 58.9 | K110: =Tabelle2[[#This Row],[Anz]]*Tabelle2[[#This Row],[EH-Preis]] -> 58.9
A111: 42761 | B111: 12.5 | C111: h | D111: Montage | E111: uh | F111: Arbeit | G111: Arbeit | H111: offen | I111: uh offen | J111: 25 | K111: =Tabelle2[[#This Row],[Anz]]*Tabelle2[[#This Row],[EH-Preis]] -> 312.5
A112: 42761 | B112: 1 | C112: Pa | D112: Montage | E112: Hornbach | G112: Material | H112: bezahlt | J112: 340.8 | K112: =Tabelle2[[#This Row],[Anz]]*Tabelle2[[#This Row],[EH-Preis]] -> 340.8
A113: 42762 | B113: 9 | C113: h | D113: Montage | E113: uh | F113: Arbeit | G113: Arbeit | H113: offen | I113: uh offen | J113: 25 | K113: =Tabelle2[[#This Row],[Anz]]*Tabelle2[[#This Row],[EH-Preis]] -> 225
A114: 42763 | B114: 1 | C114: Pa | D114: Elektro | E114: Hornbach | G114: Material | H114: bezahlt | J114: 31.2 | K114: =Tabelle2[[#This Row],[Anz]]*Tabelle2[[#This Row],[EH-Preis]] -> 31.2
A115: 42763 | B115: 1 | C115: Pa | D115: Fliesen | E115: Obi | F115: diverses | G115: Material | H115: bez | I115: MAD | J115: 217.6 | K115: =Tabelle2[[#This Row],[Anz]]*Tabelle2[[#This Row],[EH-Preis]] -> 217.6
A116: 42763 | B116: 1 | C116: Pa | D116: Maler | E116: Obi | F116: diverses | G116: Material | H116: bez | I116: MAD | J116: 60 | K116: =Tabelle2[[#This Row],[Anz]]*Tabelle2[[#This Row],[EH-Preis]] -> 60
...

Sheet DATENBANK
A1: Geschosse
B2: KELLERGESCHOSS | C2: KG
B3: ERDGESCHOSS | C3: EG
B4: 1. OBERGESCHOSS | C4: 1. OG
B5: 2. OBERGESCHOSS | C5: 2. OG
B6: 3. OBERGESCHOSS | C6: 3. OG
B7: 4. OBERGESCHOSS | C7: 4. OG
B8: 5. OBERGESCHOSS | C8: 5. OG
B9: 6. OBERGESCHOSS | C9: 6. OG
B10: 7. OBERGESCHOSS | C10: 7. OG
B11: 8. OBERGESCHOSS | C11: 8. OG
B12: 9. OBERGESCHOSS | C12: 9. OG
B13: 10. OBERGESCHOSS | C13: 10. OG
... B15: Sonstige Fl | C15: SF
A17: Flächenart
B18: Hauptnutzfläche | C18: HNF
B19: Nebennutzfläche | C19: NNF
B20: Verkehresfläche | C20: VF
B21: Freifläche | C21: FF
B22: Allgemein Fläche | C22: Allg. Fl.
A24: Raum
B25: Vorzimmer
B26: WC
B27: Küche
B28: Essen / Wohnen
B29: Gang
B30: Stiegenhaus EG-OG
B31: Teichzimmer
B32: Bad
B33: Garagenzimmer
B34: Diele
B35: Bad - OG
B36: Apartment
... B50: Terrasse
A52: Baukosten
B53: ALLGEMEIN
B54: AUFSCHLIESSUNG
B55: BAUMEISTER
B56: HOLZBAU
B57: STAHLBAU & SCHLOSSER
...

Sheet BKS
A1: 100
B4: ELEKTRO
C5: Verteilerkasten | D5: 1 | E5: Stk. | F5: Schläuche, Kabel, UP-Dosen | H5: HNF | I5: 750 | J5: 800
C6: Rohinstallation | D6: =$A$1 -> 100 | E6: m² | F6: Schläuche, Kabel, UP-Dosen | H6: HNF | I6: 25 | J6: 15
C7: Einsatz | E7: Stk. | F7: Schläuche, Kabel, UP-Dosen | H7: HNF | I7: 25 | J7: 12
C8: Rahmen | E8: Stk. | F8: Schalter - Stecker Rahmen neu | H8: HNF | I8: 15 | J8: 19
C10: name | D10: BKprom2
C11: ALLGEMEIN | D11: 1.88
C12: Baustelle einrichten | D12: 3
C13: Baustrom | D13: 4
C14: Baustelle frei machen | D14: 1.5
C15: Baustelle sichern | D15: 1.5
C16: Baustelle reinigen | D16: 1.5
C17: Bauherrleistungen | D17: 0
C18: Bestandaufnahme | D18: 1.5
C19: Bestandsgutachen | D19: 0
C20: Abfindungen | D20: 1.5
C21: Ablösen | D21: 1.5
C22: Allgemeine Maßnahmen | D22: 1.5
... C101: Reserven | D101: 5

Sheet Vergleich
A1: Hausname | B1: Wintergartenhaus | C1: Haus mit Schwimmteich | D1: Altbau | E1: Langhaus mit Aussentreppe | F1: Haus mit Schmimmbad | G1: Braunes Haus | H1: Lannach | I1: Metallaussentreppenhaus
A2: Kaufpreis | B2: 289000 | C2: 255000 | D2: 98000 | E2: 275000 | F2: 297000 | G2: 210000 | H2: 230000 | I2: 289000
A3: Ort | B3: 8302 Nestelbach bei Graz | C3: 8345 Straden | D3: 8333 Riegersburg | E3: 8054 Seiersberg-Pirka | F3: 8321 St. Margarethen /Raab | G3: 8412 Allerheiligen b. Wildon | H3: 8502 Lannach | I3: 8564 Krottendorf
A4: Verfügbarkeit | B4: nach Vereinbarung | C4: ab sofort | D4: ab sofort / 3 Monate ba Kauf? | E4: ab sofort | F4: 42947 | G4: ab sofort | H4: ? | I4: ab sofort
A5: Foto
A6: Adresse | B6: Kogelbuch 32 | E6: Hauptstrasse 27 | G6: Siebing 39 | H6: Mittergasse | I6: Klei Gaisfeld 73
A7: Baujahr | B7: 1987 | D7: Ende 50er Jahre | E7: 1996 | F7: Neubau | G7: 1983 | H7: 1963/ teilsaniert | I7: 1978
A8: Wohnfläche m2 | B8: 168 | C8: 204 | D8: 140 | E8: 190 | F8: 180 | G8: 187 | H8: 145 | I8: 183
A9: Grundfläche m2 | B9: 1019 | C9: 840 | D9: 620 | E9: 525 | F9: 2022 | G9: 3809 | H9: 995 | I9: 1300
A10: Anzahl Zimmer | B10: 5 | C10: 6 | D10: 6 | E10: 4 | F10: 6 | G10: 3.5 + 2 DG auszubauen | H10: 5 | I10: 6
A11: Küchen | B11: 1 | C11: 1 | D11: 1 | E11: 2 | F11: 1 | G11: 1 | H11: 1 | I11: 1
A12: Anzahl WC | B12: 3 | C12: 2 | D12: 1 | E12: 2 | F12: 2 | G12: 1 + 1 DG | H12: 2 | I12: 2
A13: Badezimmer | B13: 3 | C13: 2 | D13: 1 | E13: 2 | F13: 1 | G13: 1 + 1 Douche DG | H13: 2 | I13: 2
A14: Zustand | B14: sehr gut, Riegelbau | C14: gut / sehr gut | D14: Altbau | E14: gut, laufend renoviert | F14: Neubau | G14: gut / sehr gut | H14: teils sanierungsbedürftig | I14: ?
A15: nötige Baumassnahmen | D15: ? | E15: Innentreppe
A16: Heizsystem | B16: E-Heizung, Solar vorbereitet | C16: Öl / Solar / Photovoltaik | D16: Kachelöfen, Tischherd, Infrarot teilw. | H16: ? | I16: Öl Zentral
A17: Dach | B17: Ziegel | C17: Ziegel | D17: Ziegel | E17: Ziegel | F17: Erdwärme | H17: Ziegel | I17: Eternit
A18: Etagen | B18: 2 | C18: 2 | E18: 2 | F18: 2 | G18: 2 | H18: 2 | I18: 2
A19: Keller | B19: ja | C19: ja, grosszügig | D19: 70m2 | F19: ja | G19: ja | H19: ja | I19: ja
A20: Externe Gebäude | E20: Gartenhütte, Weinlaube, Biotop, Brunnen, Gewölbekeller | F20: Gartenhaus, Schwimmbad | G20: Gartenschopf | I20: Schopf zum Sitzen
A21: Autoabstellplatz | B21: Carport 1 | C21: Garage, Carport | D21: Garage | E21: 4 offene Plätze | F21: 2 mit Werkraum | G21: Garage | H21: Garage | I21: Carport 2
A23: KP / m2 Wohnraum | B23: =B2/B8 -> 1720.2381 | C23: =C2/C8 -> 1250 | D23: =D2/D8 -> 700 | E23: =E2/E8 -> 1447.3684 | F23: =F2/F8 -> 1650 | G23: =G2/G8 -> 1122.9947 | H23: =H2/H8 -> 1586.2069 | I23: =I2/I8 -> 1579.235
A24: KP / m2 Grundfläche | B24: =B2/B9 -> 283.61138 | C24: =C2/C9 -> 303.57143 | D24: =D2/D9 -> 158.06452 | E24: =E2/E9 -> 523.80952 | F24: =F2/F9 -> 146.88427 | G24: =G2/G9 -> 55.132581 | H24: =H2/H9 -> 231.15578 | I24: =I2/I9 -> 222.30769
A26: Kontakt am | B26: 42588 | C26: 42590 | D26: 42590 | E26: 42588 | F26: 42590 | G26: 42589 | H26: 42590 | I26: 42590
A27: Verkäufer | B27: Regina Genser | C27: Herbert Bauer | D27: Herr Parmettler | E27: Franz Weinhandel | F27: Hr. Nitsch | G27: Harald Paulich | H27: Dipl Ing. Georg Fragz | I27: Christian Nebel
A28: Link | B28: www.willhaben.at/iad/immobilien/haus-kaufen/steiermark/graz-umgebung/entzückende-grüne-oase-mit-wintergartentraum-168089258 | C28: www.willhaben.at/iad/immobilien/haus-kaufen/steiermark/suedoststeiermark/schoenes-einfamilienhaus-mit-schwimmteich-in-traumhafter-sonnenlage-naehe-gnas-und-gleichenberg-169691352/ | E28: www.willhaben.at/iad/immobilien/haus-kaufen/graz/familienhaus-in-ruhiger-ortslage-128669602/ | F28: www.willhaben.at/iad/immobilien/haus-kaufen/steiermark/weiz/einfamilienhaus-naehe-gleisdorf-168618995/ | G28: www.willhaben.at/iad/immobilien/haus-kaufen/steiermark/Leibnitz/rückzugsort-fuer-die-familie-169276359 | H28: www.immoads.oe24.at/immobilien/haus-kaufen/steiermark/Deutschlandsberg/8502-Lannach/00078861-willkommen-im-familienglueck | I28: www.willhaben.at/iad/immobilien/haus-kaufen/steiermark/voitsberg/wohnhaus-in-ruhiger-sonniger-lage-in-klein-gaisfeld-krottendorf-165759785/
A29: Telefon | B29: +43 664 362 42 98 | C29: +43 664 849 45 14 | D29: +43 664 250 87 78 | E29: +43 664 84 94 517 | F29: +43 664 845 11 583 | H29: +43 680 201 35 30 | I29: +43 664 855 01 06
A30: Objektnummer | B30: 107254 | H30: 78861
E31: fw@neuimmo.com | H31: innoestate
A32: Energieausweis | C32: in Arbeit
A33: HWB (kwh/m2/Jahr | B33: 67 | D33: 270 | E33: 140 | F33: 47 | G33: 94.7 | H33: ? | I33: 77.88
A34: HWB Energieklasse | B34: C | E34: D | G34: C | H34: ? | I34: C
A35: fGee Energieklasse | B35: 1.6 | D35: 3.34 | E35: XX | G35: 1.38 | H35: ? | I35: 1.24
A36: fGee Energieklasse | B36: C | G36: C | H36: ? | I36: C
I37: Karin Ranegger
I38: + 43 3457 4077-88
I39: karin.ranegger@rlb-stmk.raiffeisen.at

Sheet Finanzierung
B1: Start BSPK | D1: WÜRO BSPK | F1: Hypo Stmk. | H1: Steiermärk.
A3: Finanzierungssumme | B3: 157605.82 | D3: 157805.43 | F3: 157500 | H3: 157500
A4: Auszahlungssumme | B4: 150000 | D4: 150000 | F4: 149784.5 | H4: 150244
A5: Laufzeit | B5: 240 | D5: 228 | F5: 180 | H5: 185
A6: Monatliche Rate | B6: 814.76 | D6: 838.68 | F6: 996.92 | H6: 1023.74
B7: =(B6*12)/B3 -> 0.062035273 | D7: =(D6*12)/D3 -> 0.063775752 | F7: =(F6*12)/F3 -> 0.07595581 | H7: =(H6*12)/H3 -> 0.077999238
A9: Kondition Kredit/ Darlehen | B9: 0.01375 | D9: 0.01375 | F9: 0.01625 | H9: 0.0175
A10: Fixzins für 5 Jahre | F10: 5 Jahre
A11: Fixzins für 10 Jahre | B11: 0.021 | D11: 0.022 | H11: 0.01875
A12: anschließend variabel min. | B12: 0.019 | D12: 0.023 | H12: 0.0175
A13: anschließend variabel max. | B13: 0.06 | D13: 0.06
A14: Basis 3 Mon. Eurib./ 12 Mon. Eurib. | B14: 0 | D14: 0 | F14: 0 | H14: 0
A15: Zinssatz effektiv | B15: 0.0276 | D15: 0.029 | F15: 0.024 | H15: 0.023
A16: Gesamtbelastung | B16: 194551.5 | D16: 210567 | F16: 179338.57 | H16: 186611.57
A17: GB Eintragung | B17: 2219 | D17: 2160 | F17: 2268 | H17: 2280
B18: =B17/B34 -> 0.011732858 | D18: =D17/D34 -> 0.011406452 | F18: =F17/F34 -> 0.012 | H18: =H17/H34 -> 0.012063492
A20: Kreditkosten
A21: Bearbeitung/ Bereitstellung | B21: 0.03 | D21: 0.03 | F21: 0.03 | H21: 0.03
A22: GB Gesuch (ca.) | B22: k.A. | D22: 74 | F22: 66 | H22: 37
A23: sonstige (Bewertung) | B23: k.A. | D23: k.A. | F23: 280 | H23: 280
A24: Begl. PU Bank (ca.) | B24: 136.82 | D24: k.A. | F24: 198.5 | H24: k. A.
A25: Verwaltungskostenbeitrag | B25: 750 | D25: 1071.43 | F25: 220 | H25: 100
A26: Kontoführung pro Quartal | B26: 15.6 | D26: 11.44 | F26: 15.34 | H26: 14.48
A27: in mtl. Rate enthalten | B27: ja | D27: ja | F27: ja | H27: ja
A28: GB Auszug Min. 2x pro Jahr | B28: - | D28: ja | F28: - | H28: -
A29: (bei Hinterlegung PU)
A31: Bedingungen
A32: Stille Gehaltsverpfändung | B32: ja | D32: ja | F32: ja | H32: ja
A33: Pfandrechtseintragung | B33: 1.2 | D33: 1.2 | F33: 1.2 | H33: 1.2
A34: Pfandrechtsbetrag | B34: =B33*B3 -> 189126.98 | D34: =D33*D3 -> 189366.52 | F34: =F33*F3 -> 189000 | H34: =H33*H3 -> 189000
A35: Abtretung Risiko | B35: nein | D35: nein | F35: nein | H35: nein
A36: Nachweis Eigenmittel | B36: nein | D36: nein | F36: ja | H36: ja
A37: Treuhandabwicklung | B37: ja | D37: ja | F37: ja | H37: ja
A38: Girokonto Beide | B38: nein | D38: nein | F38: k.A. | H38: ja
A39: Umzug nach Ö (Hauptwohnsitz) | B39: ja | D39: ja | F39: ja | H39: ja

Sheet Baupreise
A1: PosNr | B1: Prio | C1: Ebene | D1: Raum | E1: Gewerk | F1: Anz. | G1: EH | H1: Position | I1: Beschreibung | J1: Zeit | K1: EH-Arbeit | L1: Arbeit | M1: EH-Material2 | N1: Material | O1: Pos.Preis
A2: 2 | B2: - | F2: Teichzimmer
A3: 2_1 | B3: Hoch | C3: EG | D3: Teichzimmer | E3: BAUMEISTER | F3: =Flächen!F11 -> 12.21 | G3: m² | H3: Decke GKP | I3: 9,5 mm | J3: 2 | K3: 20 | L3: =Tabelle14[[#This Row],[Anz.]]*Tabelle14[[#This Row],[EH-Arbeit]] -> 244.2 | M3: 5 | N3: =Tabelle14[[#This Row],[Anz.]]+Tabelle14[[#This Row],[EH-Material2]] -> 17.21 | O3: =(Tabelle14[[#This Row],[EH-Material2]]+Tabelle14[[#This Row],[EH-Arbeit]])*Tabelle14[[#This Row],[Anz.]] -> 305.25
A4: 2_4 | B4: Hoch | C4: EG | D4: Teichzimmer | E4: ELEKTRO | F4: 1 | G4: Stk. | H4: Beleuchtung | I4: Deckenlicht - Fassung | J4: 0.25 | K4: 5 | L4: =Tabelle14[[#This Row],[Anz.]]*Tabelle14[[#This Row],[EH-Arbeit]] -> 5 | M4: 6 | N4: =Tabelle14[[#This Row],[Anz.]]+Tabelle14[[#This Row],[EH-Material2]] -> 7 | O4: =(Tabelle14[[#This Row],[EH-Material2]]+Tabelle14[[#This Row],[EH-Arbeit]])*Tabelle14[[#This Row],[Anz.]] -> 11
A5: 2_5 | B5: Hoch | C5: EG | D5: Teichzimmer | E5: MALER | F5: 1 | G5: Stk. | H5: Heizkörper lackieren | I5: weiss | J5: 0.25 | K5: 23 | L5: =Tabelle14[[#This Row],[Anz.]]*Tabelle14[[#This Row],[EH-Arbeit]] -> 23 | M5: 12 | N5: =Tabelle14[[#This Row],[Anz.]]+Tabelle14[[#This Row],[EH-Material2]] -> 13 | O5: =(Tabelle14[[#This Row],[EH-Material2]]+Tabelle14[[#This Row],[EH-Arbeit]])*Tabelle14[[#This Row],[Anz.]] -> 35
A6: 2_6 | B6: Hoch | C6: EG | D6: Teichzimmer | E6: MALER | F6: =Flächen!F11 -> 12.21 | G6: m² | H6: Spachteln | I6: Klimaglätte | J6: 3 | K6: 8 | L6: =Tabelle14[[#This Row],[Anz.]]*Tabelle14[[#This Row],[EH-Arbeit]] -> 97.68 | M6: 3 | N6: =Tabelle14[[#This Row],[Anz.]]+Tabelle14[[#This Row],[EH-Material2]] -> 15.21 | O6: =(Tabelle14[[#This Row],[EH-Material2]]+Tabelle14[[#This Row],[EH-Arbeit]])*Tabelle14[[#This Row],[Anz.]] -> 134.31
A7: 2_7 | B7: Hoch | C7: EG | D7: Teichzimmer | E7: ELEKTRO | F7: =Flächen!F11 -> 12.21 | G7: m² | H7: Rohinstallation | I7: Kabel u. UP - Dosen | J7: 0.25 | K7: 6 | L7: =Tabelle14[[#This Row],[Anz.]]*Tabelle14[[#This Row],[EH-Arbeit]] -> 73.26 | M7: 4 | N7: =Tabelle14[[#This Row],[Anz.]]+Tabelle14[[#This Row],[EH-Material2]] -> 16.21 | O7: =(Tabelle14[[#This Row],[EH-Material2]]+Tabelle14[[#This Row],[EH-Arbeit]])*Tabelle14[[#This Row],[Anz.]] -> 122.1
